2024-07-02 10:34:10,752 INFO    MainThread:4067 [wandb_setup.py:_flush():75] Loading settings from /home/user/.config/wandb/settings
2024-07-02 10:34:10,753 INFO    MainThread:4067 [wandb_setup.py:_flush():75] Loading settings from /media/hdd_stockage/home/user/SpeciesDetection/marine-detect/wandb/settings
2024-07-02 10:34:10,753 INFO    MainThread:4067 [wandb_setup.py:_flush():75] Loading settings from environment variables: {}
2024-07-02 10:34:10,753 INFO    MainThread:4067 [wandb_setup.py:_flush():75] Inferring run settings from compute environment: {'program_relpath': 'src/marine_detect/train.py', 'program': '/media/hdd_stockage/home/user/SpeciesDetection/marine-detect/src/marine_detect/train.py'}
2024-07-02 10:34:10,753 INFO    MainThread:4067 [wandb_init.py:_log_setup():438] Logging user logs to /media/hdd_stockage/home/user/SpeciesDetection/marine-detect/wandb/run-20240702_103410-n3at5aks/logs/debug.log
2024-07-02 10:34:10,753 INFO    MainThread:4067 [wandb_init.py:_log_setup():439] Logging internal logs to /media/hdd_stockage/home/user/SpeciesDetection/marine-detect/wandb/run-20240702_103410-n3at5aks/logs/debug-internal.log
2024-07-02 10:34:10,753 INFO    MainThread:4067 [wandb_init.py:init():472] calling init triggers
2024-07-02 10:34:10,754 INFO    MainThread:4067 [wandb_init.py:init():476] wandb.init called with sweep_config: {}
config: {'task': 'detect', 'mode': 'train', 'model': '/media/hdd_stockage/home/user/SpeciesDetection/marine-detect/model/FishInv.pt', 'data': '/media/hdd_stockage/home/user/SpeciesDetection/marine-detect/src/marine_detect/trainFishInv.yaml', 'epochs': 100, 'patience': 50, 'batch': 16, 'imgsz': 640, 'save': True, 'save_period': -1, 'cache': False, 'device': None, 'workers': 8, 'project': None, 'name': None, 'exist_ok': False, 'pretrained': True, 'optimizer': 'auto', 'verbose': True, 'seed': 0, 'deterministic': True, 'single_cls': False, 'rect': False, 'cos_lr': False, 'close_mosaic': 10, 'resume': False, 'amp': True, 'fraction': 1.0, 'profile': False, 'overlap_mask': True, 'mask_ratio': 4, 'dropout': 0.0, 'val': True, 'split': 'val', 'save_json': False, 'save_hybrid': False, 'conf': None, 'iou': 0.7, 'max_det': 300, 'half': False, 'dnn': False, 'plots': True, 'source': None, 'show': False, 'save_txt': False, 'save_conf': False, 'save_crop': False, 'show_labels': True, 'show_conf': True, 'vid_stride': 1, 'line_width': None, 'visualize': False, 'augment': False, 'agnostic_nms': False, 'classes': None, 'retina_masks': False, 'boxes': True, 'format': 'torchscript', 'keras': False, 'optimize': False, 'int8': False, 'dynamic': False, 'simplify': False, 'opset': None, 'workspace': 4, 'nms': False, 'lr0': 0.01, 'lrf': 0.01, 'momentum': 0.937, 'weight_decay': 0.0005, 'warmup_epochs': 3.0, 'warmup_momentum': 0.8, 'warmup_bias_lr': 0.1, 'box': 7.5, 'cls': 0.5, 'dfl': 1.5, 'pose': 12.0, 'kobj': 1.0, 'label_smoothing': 0.0, 'nbs': 64, 'hsv_h': 0.015, 'hsv_s': 0.7, 'hsv_v': 0.4, 'degrees': 0.0, 'translate': 0.1, 'scale': 0.5, 'shear': 0.0, 'perspective': 0.0, 'flipud': 0.0, 'fliplr': 0.5, 'mosaic': 1.0, 'mixup': 0.0, 'copy_paste': 0.0, 'cfg': None, 'tracker': 'botsort.yaml', 'save_dir': '/home/user/.pyenv/runs/detect/train4'}
2024-07-02 10:34:10,754 INFO    MainThread:4067 [wandb_init.py:init():525] starting backend
2024-07-02 10:34:10,754 INFO    MainThread:4067 [backend.py:_multiprocessing_setup():101] multiprocessing start_methods=fork,spawn,forkserver, using: spawn
2024-07-02 10:34:10,769 INFO    MainThread:4067 [backend.py:ensure_launched():219] starting backend process...
2024-07-02 10:34:10,777 INFO    MainThread:4067 [backend.py:ensure_launched():225] started backend process with pid: 4689
2024-07-02 10:34:10,778 INFO    MainThread:4067 [wandb_init.py:init():534] backend started and connected
2024-07-02 10:34:10,783 INFO    MainThread:4067 [wandb_init.py:init():598] updated telemetry
2024-07-02 10:34:10,808 INFO    MainThread:4067 [wandb_init.py:init():629] communicating run to backend with 30 second timeout
2024-07-02 10:34:39,058 ERROR   Thread-1  :4067 [retry.py:__call__():126] Retry attempt failed:
Traceback (most recent call last):
  File "/home/user/.pyenv/versions/3.7.4/lib/python3.7/site-packages/urllib3/connection.py", line 207, in _new_conn
    socket_options=self.socket_options,
  File "/home/user/.pyenv/versions/3.7.4/lib/python3.7/site-packages/urllib3/util/connection.py", line 60, in create_connection
    for res in socket.getaddrinfo(host, port, family, socket.SOCK_STREAM):
  File "/home/user/.pyenv/versions/3.7.4/lib/python3.7/socket.py", line 748, in getaddrinfo
    for res in _socket.getaddrinfo(host, port, family, type, proto, flags):
socket.gaierror: [Errno -2] Name or service not known

The above exception was the direct cause of the following exception:

Traceback (most recent call last):
  File "/home/user/.pyenv/versions/3.7.4/lib/python3.7/site-packages/urllib3/connectionpool.py", line 803, in urlopen
    **response_kw,
  File "/home/user/.pyenv/versions/3.7.4/lib/python3.7/site-packages/urllib3/connectionpool.py", line 492, in _make_request
    raise new_e
  File "/home/user/.pyenv/versions/3.7.4/lib/python3.7/site-packages/urllib3/connectionpool.py", line 468, in _make_request
    self._validate_conn(conn)
  File "/home/user/.pyenv/versions/3.7.4/lib/python3.7/site-packages/urllib3/connectionpool.py", line 1097, in _validate_conn
    conn.connect()
  File "/home/user/.pyenv/versions/3.7.4/lib/python3.7/site-packages/urllib3/connection.py", line 611, in connect
    self.sock = sock = self._new_conn()
  File "/home/user/.pyenv/versions/3.7.4/lib/python3.7/site-packages/urllib3/connection.py", line 210, in _new_conn
    raise NameResolutionError(self.host, self, e) from e
urllib3.exceptions.NameResolutionError: <urllib3.connection.HTTPSConnection object at 0x7f56be568e10>: Failed to resolve 'api.wandb.ai' ([Errno -2] Name or service not known)

The above exception was the direct cause of the following exception:

Traceback (most recent call last):
  File "/home/user/.pyenv/versions/3.7.4/lib/python3.7/site-packages/requests/adapters.py", line 497, in send
    chunked=chunked,
  File "/home/user/.pyenv/versions/3.7.4/lib/python3.7/site-packages/urllib3/connectionpool.py", line 846, in urlopen
    method, url, error=new_e, _pool=self, _stacktrace=sys.exc_info()[2]
  File "/home/user/.pyenv/versions/3.7.4/lib/python3.7/site-packages/urllib3/util/retry.py", line 515, in increment
    raise MaxRetryError(_pool, url, reason) from reason  # type: ignore[arg-type]
urllib3.exceptions.MaxRetryError: HTTPSConnectionPool(host='api.wandb.ai', port=443): Max retries exceeded with url: /graphql (Caused by NameResolutionError("<urllib3.connection.HTTPSConnection object at 0x7f56be568e10>: Failed to resolve 'api.wandb.ai' ([Errno -2] Name or service not known)"))

During handling of the above exception, another exception occurred:

Traceback (most recent call last):
  File "/home/user/.pyenv/versions/3.7.4/lib/python3.7/site-packages/wandb/sdk/lib/retry.py", line 102, in __call__
    result = self._call_fn(*args, **kwargs)
  File "/home/user/.pyenv/versions/3.7.4/lib/python3.7/site-packages/wandb/sdk/internal/internal_api.py", line 141, in execute
    return self.client.execute(*args, **kwargs)
  File "/home/user/.pyenv/versions/3.7.4/lib/python3.7/site-packages/wandb/vendor/gql-0.2.0/wandb_gql/client.py", line 52, in execute
    result = self._get_result(document, *args, **kwargs)
  File "/home/user/.pyenv/versions/3.7.4/lib/python3.7/site-packages/wandb/vendor/gql-0.2.0/wandb_gql/client.py", line 60, in _get_result
    return self.transport.execute(document, *args, **kwargs)
  File "/home/user/.pyenv/versions/3.7.4/lib/python3.7/site-packages/wandb/vendor/gql-0.2.0/wandb_gql/transport/requests.py", line 38, in execute
    request = requests.post(self.url, **post_args)
  File "/home/user/.pyenv/versions/3.7.4/lib/python3.7/site-packages/requests/api.py", line 115, in post
    return request("post", url, data=data, json=json, **kwargs)
  File "/home/user/.pyenv/versions/3.7.4/lib/python3.7/site-packages/requests/api.py", line 59, in request
    return session.request(method=method, url=url, **kwargs)
  File "/home/user/.pyenv/versions/3.7.4/lib/python3.7/site-packages/requests/sessions.py", line 589, in request
    resp = self.send(prep, **send_kwargs)
  File "/home/user/.pyenv/versions/3.7.4/lib/python3.7/site-packages/requests/sessions.py", line 703, in send
    r = adapter.send(request, **kwargs)
  File "/home/user/.pyenv/versions/3.7.4/lib/python3.7/site-packages/requests/adapters.py", line 519, in send
    raise ConnectionError(e, request=request)
requests.exceptions.ConnectionError: HTTPSConnectionPool(host='api.wandb.ai', port=443): Max retries exceeded with url: /graphql (Caused by NameResolutionError("<urllib3.connection.HTTPSConnection object at 0x7f56be568e10>: Failed to resolve 'api.wandb.ai' ([Errno -2] Name or service not known)"))
2024-07-02 10:34:40,811 INFO    MainThread:4067 [interface_shared.py:_communicate_run():325] couldn't get run from backend
2024-07-02 10:34:40,811 ERROR   MainThread:4067 [wandb_init.py:init():634] backend process timed out
2024-07-02 10:34:40,812 ERROR   MainThread:4067 [wandb_init.py:init():645] encountered error: Error communicating with wandb process
try: wandb.init(settings=wandb.Settings(start_method='fork'))
or:  wandb.init(settings=wandb.Settings(start_method='thread'))
For more info see: https://docs.wandb.ai/library/init#init-start-error
2024-07-02 10:35:35,942 WARNING MainThread:4067 [wandb_init.py:init():1017] interrupted
Traceback (most recent call last):
  File "/home/user/.pyenv/versions/3.7.4/lib/python3.7/site-packages/wandb/sdk/wandb_init.py", line 996, in init
    run = wi.init()
  File "/home/user/.pyenv/versions/3.7.4/lib/python3.7/site-packages/wandb/sdk/wandb_init.py", line 649, in init
    backend.cleanup()
  File "/home/user/.pyenv/versions/3.7.4/lib/python3.7/site-packages/wandb/sdk/backend/backend.py", line 250, in cleanup
    self.wandb_process.join()
  File "/home/user/.pyenv/versions/3.7.4/lib/python3.7/multiprocessing/process.py", line 140, in join
    res = self._popen.wait(timeout)
  File "/home/user/.pyenv/versions/3.7.4/lib/python3.7/multiprocessing/popen_fork.py", line 48, in wait
    return self.poll(os.WNOHANG if timeout == 0.0 else 0)
  File "/home/user/.pyenv/versions/3.7.4/lib/python3.7/multiprocessing/popen_fork.py", line 28, in poll
    pid, sts = os.waitpid(self.pid, flag)
KeyboardInterrupt
